Workbook
Name avgVelocity: '[1]Cone of Uncertainty'!$C$14
Name avgVelocity: 'Cone of Uncertainty'!$D$13
Name BusinessUncertainty: '[1]ConeOfUncertainty Setup'!$N$3:$N$5
Name BusinessUncertainty: 'ConeOfUncertainty Setup'!$O$4:$O$6
Name exchangerate: '[1]FY21 Exchange Rates'!$B$4:$C$20
Name exchangerate: #REF!
Name grades: #REF!
Name locations: [1]Locations!$A$1:$B$27
Name locations: #REF!
Name lst_SP_to_TShirt: '[1]ConeOfUncertainty Setup'!$I$16:$J$25
Name lst_SP_to_TShirt: 'ConeOfUncertainty Setup'!$J$13:$K$22
Name lst_TShirt_2_SP_Avg: '[1]ConeOfUncertainty Setup'!$I$3:$J$9
Name lst_TShirt_2_SP_Avg: 'ConeOfUncertainty Setup'!$J$4:$K$10
Name lst_tshirt_bu: '[1]ConeOfUncertainty Setup'!$B$3:$E$9
Name lst_tshirt_bu: 'ConeOfUncertainty Setup'!$C$4:$F$10
Name lst_tshirt_tc: '[1]ConeOfUncertainty Setup'!$B$12:$E$18
Name lst_tshirt_tc: 'ConeOfUncertainty Setup'!$C$13:$F$19
Name rates: #REF!
Name rates: #REF!
Name stdcost: '[1]FY21 SCM - GBP'!$A$8:$I$384
Name stdcost: #REF!
Name TechnicalComplexity: '[1]ConeOfUncertainty Setup'!$R$3:$R$5
Name TechnicalComplexity: 'ConeOfUncertainty Setup'!$O$13:$O$15
Name val_phases: '[1]ConeOfUncertainty Setup'!$V$3:$V$5
Name val_phases: 'ConeOfUncertainty Setup'!$S$4:$S$6
Name val_phases_all: 'ConeOfUncertainty Setup'!$S$4:$S$7
Name val_SP: '[1]ConeOfUncertainty Setup'!$I$16:$I$25
Name val_SP: 'ConeOfUncertainty Setup'!$J$13:$J$22
Name val_TShirt: '[1]ConeOfUncertainty Setup'!$I$3:$I$9
Name val_TShirt: 'ConeOfUncertainty Setup'!$J$4:$J$10
Name XS: Features!$N$6

Sheet Features
A1: Features backlog
A2: ID | B2: Capability | C2: Backlog Item (Feature or Story) | D2: Comments | E2: Phase | F2: Tshirt Sizing | G2: Story Points | H2: Business Uncertainty | I2: Technical Complexity | J2: BEST CASE | K2: MOST LIKELY | L2: WORST CASE | M2: CONE of Uncertainty | N2: Tshirt Size for Cone Calc
A3: 1 | B3: Pantalla Cliente | C3: formulario de registro | D3: formulario de registro de cliente | E3: Next | F3: S | G3: 5 | H3: Low | I3: Medium | J3: =IFERROR((K3-K3*M3),0) -> 4.75 | K3: =IFERROR((IF(ISBLANK(G3),VLOOKUP(F3,lst_TShirt_2_SP_Avg,2,FALSE),G3)),0) -> 5 | L3: =IFERROR((K3+K3*M3),0) -> 5.25 | M3: =IF(H3="Low",VLOOKUP(N3,lst_tshirt_bu,2,FALSE),IF(H3="Medium",VLOOKUP(N3,lst_tshirt_bu,3,FALSE),IF(H3="High",VLOOKUP(N3,lst_tshirt_bu,4,FALSE),0))) + IF(I3="Low",VLOOKUP(N3,lst_tshirt_tc,2,FALSE),IF(I3="Medium",VLOOKUP(N3,lst_tshirt_tc,3,FALSE),IF(I3="High",VLOOKUP(N3,lst_tshirt_tc,4,FALSE),0))) -> 0.05 | N3: =IF(ISBLANK(G3),F3,VLOOKUP(G3,lst_SP_to_TShirt,2,FALSE)) -> S
A4: 2 | B4: Pantalla Cliente | C4: Login | D4: SSO SQL | E4: Next | F4: M | G4: 8 | H4: Low | I4: High | J4: =IFERROR((K4-K4*M4),0) -> 6.4 | K4: =IFERROR((IF(ISBLANK(G4),VLOOKUP(F4,lst_TShirt_2_SP_Avg,2,FALSE),G4)),0) -> 8 | L4: =K4+K4*M4 -> 9.6 | M4: =IF(H4="Low",VLOOKUP(N4,lst_tshirt_bu,2,FALSE),IF(H4="Medium",VLOOKUP(N4,lst_tshirt_bu,3,FALSE),IF(H4="High",VLOOKUP(N4,lst_tshirt_bu,4,FALSE),0))) + IF(I4="Low",VLOOKUP(N4,lst_tshirt_tc,2,FALSE),IF(I4="Medium",VLOOKUP(N4,lst_tshirt_tc,3,FALSE),IF(I4="High",VLOOKUP(N4,lst_tshirt_tc,4,FALSE),0))) -> 0.2 | N4: =IF(ISBLANK(G4),F4,VLOOKUP(G4,lst_SP_to_TShirt,2,FALSE)) -> M
A5: 3 | B5: Pantalla Cliente | C5: Agendamiento citas | D5: formulario de agendamiento | E5: Next | F5: M | G5: 8 | H5: Low | I5: Low | J5: =IFERROR((K5-K5*M5),0) -> 8 | K5: =IFERROR((IF(ISBLANK(G5),VLOOKUP(F5,lst_TShirt_2_SP_Avg,2,FALSE),G5)),0) -> 8 | L5: =K5+K5*M5 -> 8 | M5: =IF(H5="Low",VLOOKUP(N5,lst_tshirt_bu,2,FALSE),IF(H5="Medium",VLOOKUP(N5,lst_tshirt_bu,3,FALSE),IF(H5="High",VLOOKUP(N5,lst_tshirt_bu,4,FALSE),0))) + IF(I5="Low",VLOOKUP(N5,lst_tshirt_tc,2,FALSE),IF(I5="Medium",VLOOKUP(N5,lst_tshirt_tc,3,FALSE),IF(I5="High",VLOOKUP(N5,lst_tshirt_tc,4,FALSE),0))) -> 0 | N5: =IF(ISBLANK(G5),F5,VLOOKUP(G5,lst_SP_to_TShirt,2,FALSE)) -> M
A6: 4 | B6: Capability 1 | C6: sistema de calificacion | D6: use modelo de estrellas para lavador | E6: Next | F6: S | G6: 3 | H6: Low | I6: Medium | J6: =IFERROR((K6-K6*M6),0) -> 2.85 | K6: =IFERROR((IF(ISBLANK(G6),VLOOKUP(F6,lst_TShirt_2_SP_Avg,2,FALSE),G6)),0) -> 3 | L6: =K6+K6*M6 -> 3.15 | M6: =IF(H6="Low",VLOOKUP(N6,lst_tshirt_bu,2,FALSE),IF(H6="Medium",VLOOKUP(N6,lst_tshirt_bu,3,FALSE),IF(H6="High",VLOOKUP(N6,lst_tshirt_bu,4,FALSE),0))) + IF(I6="Low",VLOOKUP(N6,lst_tshirt_tc,2,FALSE),IF(I6="Medium",VLOOKUP(N6,lst_tshirt_tc,3,FALSE),IF(I6="High",VLOOKUP(N6,lst_tshirt_tc,4,FALSE),0))) -> 0.05 | N6: =IF(ISBLANK(G6),F6,VLOOKUP(G6,lst_SP_to_TShirt,2,FALSE)) -> S
A7: 5 | B7: Capability 1 | C7: Feature 5 | E7: Next | F7: zero | H7: Low | I7: Low | J7: =IFERROR((K7-K7*M7),0) -> 0 | K7: =IFERROR((IF(ISBLANK(G7),VLOOKUP(F7,lst_TShirt_2_SP_Avg,2,FALSE),G7)),0) -> 0 | L7: =K7+K7*M7 -> 0 | M7: =IF(H7="Low",VLOOKUP(N7,lst_tshirt_bu,2,FALSE),IF(H7="Medium",VLOOKUP(N7,lst_tshirt_bu,3,FALSE),IF(H7="High",VLOOKUP(N7,lst_tshirt_bu,4,FALSE),0))) + IF(I7="Low",VLOOKUP(N7,lst_tshirt_tc,2,FALSE),IF(I7="Medium",VLOOKUP(N7,lst_tshirt_tc,3,FALSE),IF(I7="High",VLOOKUP(N7,lst_tshirt_tc,4,FALSE),0))) -> 0 | N7: =IF(ISBLANK(G7),F7,VLOOKUP(G7,lst_SP_to_TShirt,2,FALSE)) -> zero
A8: 6 | B8: Capability 1 | C8: Feature 6 | E8: Next | F8: zero | H8: Low | I8: Low | J8: =IFERROR((K8-K8*M8),0) -> 0 | K8: =IFERROR((IF(ISBLANK(G8),VLOOKUP(F8,lst_TShirt_2_SP_Avg,2,FALSE),G8)),0) -> 0 | L8: =K8+K8*M8 -> 0 | M8: =IF(H8="Low",VLOOKUP(N8,lst_tshirt_bu,2,FALSE),IF(H8="Medium",VLOOKUP(N8,lst_tshirt_bu,3,FALSE),IF(H8="High",VLOOKUP(N8,lst_tshirt_bu,4,FALSE),0))) + IF(I8="Low",VLOOKUP(N8,lst_tshirt_tc,2,FALSE),IF(I8="Medium",VLOOKUP(N8,lst_tshirt_tc,3,FALSE),IF(I8="High",VLOOKUP(N8,lst_tshirt_tc,4,FALSE),0))) -> 0 | N8: =IF(ISBLANK(G8),F8,VLOOKUP(G8,lst_SP_to_TShirt,2,FALSE)) -> zero
A9: 7 | B9: Capability 1 | C9: Feature 7 | E9: Last | F9: zero | H9: Medium | I9: Medium | J9: =IFERROR((K9-K9*M9),0) -> 0 | K9: =IFERROR((IF(ISBLANK(G9),VLOOKUP(F9,lst_TShirt_2_SP_Avg,2,FALSE),G9)),0) -> 0 | L9: =K9+K9*M9 -> 0 | M9: =IF(H9="Low",VLOOKUP(N9,lst_tshirt_bu,2,FALSE),IF(H9="Medium",VLOOKUP(N9,lst_tshirt_bu,3,FALSE),IF(H9="High",VLOOKUP(N9,lst_tshirt_bu,4,FALSE),0))) + IF(I9="Low",VLOOKUP(N9,lst_tshirt_tc,2,FALSE),IF(I9="Medium",VLOOKUP(N9,lst_tshirt_tc,3,FALSE),IF(I9="High",VLOOKUP(N9,lst_tshirt_tc,4,FALSE),0))) -> 0 | N9: =IF(ISBLANK(G9),F9,VLOOKUP(G9,lst_SP_to_TShirt,2,FALSE)) -> zero
A10: 8 | B10: Capability 1 | C10: Feature 8 | E10: Next | F10: zero | H10: Medium | I10: Low | J10: =IFERROR((K10-K10*M10),0) -> 0 | K10: =IFERROR((IF(ISBLANK(G10),VLOOKUP(F10,lst_TShirt_2_SP_Avg,2,FALSE),G10)),0) -> 0 | L10: =K10+K10*M10 -> 0 | M10: =IF(H10="Low",VLOOKUP(N10,lst_tshirt_bu,2,FALSE),IF(H10="Medium",VLOOKUP(N10,lst_tshirt_bu,3,FALSE),IF(H10="High",VLOOKUP(N10,lst_tshirt_bu,4,FALSE),0))) + IF(I10="Low",VLOOKUP(N10,lst_tshirt_tc,2,FALSE),IF(I10="Medium",VLOOKUP(N10,lst_tshirt_tc,3,FALSE),IF(I10="High",VLOOKUP(N10,lst_tshirt_tc,4,FALSE),0))) -> 0 | N10: =IF(ISBLANK(G10),F10,VLOOKUP(G10,lst_SP_to_TShirt,2,FALSE)) -> zero
A11: 9 | B11: Capability 1 | C11: Feature 9 | E11: Next | F11: zero | H11: Low | I11: Medium | J11: =IFERROR((K11-K11*M11),0) -> 0 | K11: =IFERROR((IF(ISBLANK(G11),VLOOKUP(F11,lst_TShirt_2_SP_Avg,2,FALSE),G11)),0) -> 0 | L11: =K11+K11*M11 -> 0 | M11: =IF(H11="Low",VLOOKUP(N11,lst_tshirt_bu,2,FALSE),IF(H11="Medium",VLOOKUP(N11,lst_tshirt_bu,3,FALSE),IF(H11="High",VLOOKUP(N11,lst_tshirt_bu,4,FALSE),0))) + IF(I11="Low",VLOOKUP(N11,lst_tshirt_tc,2,FALSE),IF(I11="Medium",VLOOKUP(N11,lst_tshirt_tc,3,FALSE),IF(I11="High",VLOOKUP(N11,lst_tshirt_tc,4,FALSE),0))) -> 0 | N11: =IF(ISBLANK(G11),F11,VLOOKUP(G11,lst_SP_to_TShirt,2,FALSE)) -> zero
A12: 10 | B12: Capability 1 | C12: Feature 10 | E12: Next | F12: zero | H12: Low | I12: Low | J12: =IFERROR((K12-K12*M12),0) -> 0 | K12: =IFERROR((IF(ISBLANK(G12),VLOOKUP(F12,lst_TShirt_2_SP_Avg,2,FALSE),G12)),0) -> 0 | L12: =K12+K12*M12 -> 0 | M12: =IF(H12="Low",VLOOKUP(N12,lst_tshirt_bu,2,FALSE),IF(H12="Medium",VLOOKUP(N12,lst_tshirt_bu,3,FALSE),IF(H12="High",VLOOKUP(N12,lst_tshirt_bu,4,FALSE),0))) + IF(I12="Low",VLOOKUP(N12,lst_tshirt_tc,2,FALSE),IF(I12="Medium",VLOOKUP(N12,lst_tshirt_tc,3,FALSE),IF(I12="High",VLOOKUP(N12,lst_tshirt_tc,4,FALSE),0))) -> 0 | N12: =IF(ISBLANK(G12),F12,VLOOKUP(G12,lst_SP_to_TShirt,2,FALSE)) -> zero
A13: 11 | B13: Capability 1 | C13: Feature 11 | E13: Later | F13: zero | H13: Low | I13: Low | J13: =IFERROR((K13-K13*M13),0) -> 0 | K13: =IFERROR((IF(ISBLANK(G13),VLOOKUP(F13,lst_TShirt_2_SP_Avg,2,FALSE),G13)),0) -> 0 | L13: =K13+K13*M13 -> 0 | M13: =IF(H13="Low",VLOOKUP(N13,lst_tshirt_bu,2,FALSE),IF(H13="Medium",VLOOKUP(N13,lst_tshirt_bu,3,FALSE),IF(H13="High",VLOOKUP(N13,lst_tshirt_bu,4,FALSE),0))) + IF(I13="Low",VLOOKUP(N13,lst_tshirt_tc,2,FALSE),IF(I13="Medium",VLOOKUP(N13,lst_tshirt_tc,3,FALSE),IF(I13="High",VLOOKUP(N13,lst_tshirt_tc,4,FALSE),0))) -> 0 | N13: =IF(ISBLANK(G13),F13,VLOOKUP(G13,lst_SP_to_TShirt,2,FALSE)) -> zero
A14: 12 | B14: Capability 1 | C14: Feature 12 | E14: Later | F14: zero | H14: High | I14: Medium | J14: =IFERROR((K14-K14*M14),0) -> 0 | K14: =IFERROR((IF(ISBLANK(G14),VLOOKUP(F14,lst_TShirt_2_SP_Avg,2,FALSE),G14)),0) -> 0 | L14: =K14+K14*M14 -> 0 | M14: =IF(H14="Low",VLOOKUP(N14,lst_tshirt_bu,2,FALSE),IF(H14="Medium",VLOOKUP(N14,lst_tshirt_bu,3,FALSE),IF(H14="High",VLOOKUP(N14,lst_tshirt_bu,4,FALSE),0))) + IF(I14="Low",VLOOKUP(N14,lst_tshirt_tc,2,FALSE),IF(I14="Medium",VLOOKUP(N14,lst_tshirt_tc,3,FALSE),IF(I14="High",VLOOKUP(N14,lst_tshirt_tc,4,FALSE),0))) -> 0 | N14: =IF(ISBLANK(G14),F14,VLOOKUP(G14,lst_SP_to_TShirt,2,FALSE)) -> zero
A15: 13 | B15: Capability 1 | C15: Feature 13 | E15: Next | F15: zero | H15: Low | I15: Low | J15: =IFERROR((K15-K15*M15),0) -> 0 | K15: =IFERROR((IF(ISBLANK(G15),VLOOKUP(F15,lst_TShirt_2_SP_Avg,2,FALSE),G15)),0) -> 0 | L15: =K15+K15*M15 -> 0 | M15: =IF(H15="Low",VLOOKUP(N15,lst_tshirt_bu,2,FALSE),IF(H15="Medium",VLOOKUP(N15,lst_tshirt_bu,3,FALSE),IF(H15="High",VLOOKUP(N15,lst_tshirt_bu,4,FALSE),0))) + IF(I15="Low",VLOOKUP(N15,lst_tshirt_tc,2,FALSE),IF(I15="Medium",VLOOKUP(N15,lst_tshirt_tc,3,FALSE),IF(I15="High",VLOOKUP(N15,lst_tshirt_tc,4,FALSE),0))) -> 0 | N15: =IF(ISBLANK(G15),F15,VLOOKUP(G15,lst_SP_to_TShirt,2,FALSE)) -> zero
A16: 14 | B16: Capability 2 | C16: Feature 14 | E16: Next | F16: zero | H16: Low | I16: Medium | J16: =IFERROR((K16-K16*M16),0) -> 0 | K16: =IFERROR((IF(ISBLANK(G16),VLOOKUP(F16,lst_TShirt_2_SP_Avg,2,FALSE),G16)),0) -> 0 | L16: =K16+K16*M16 -> 0 | M16: =IF(H16="Low",VLOOKUP(N16,lst_tshirt_bu,2,FALSE),IF(H16="Medium",VLOOKUP(N16,lst_tshirt_bu,3,FALSE),IF(H16="High",VLOOKUP(N16,lst_tshirt_bu,4,FALSE),0))) + IF(I16="Low",VLOOKUP(N16,lst_tshirt_tc,2,FALSE),IF(I16="Medium",VLOOKUP(N16,lst_tshirt_tc,3,FALSE),IF(I16="High",VLOOKUP(N16,lst_tshirt_tc,4,FALSE),0))) -> 0 | N16: =IF(ISBLANK(G16),F16,VLOOKUP(G16,lst_SP_to_TShirt,2,FALSE)) -> zero
A17: 15 | B17: Capability 2 | C17: Feature 15 | E17: Later | F17: zero | H17: Medium | I17: Low | J17: =IFERROR((K17-K17*M17),0) -> 0 | K17: =IFERROR((IF(ISBLANK(G17),VLOOKUP(F17,lst_TShirt_2_SP_Avg,2,FALSE),G17)),0) -> 0 | L17: =K17+K17*M17 -> 0 | M17: =IF(H17="Low",VLOOKUP(N17,lst_tshirt_bu,2,FALSE),IF(H17="Medium",VLOOKUP(N17,lst_tshirt_bu,3,FALSE),IF(H17="High",VLOOKUP(N17,lst_tshirt_bu,4,FALSE),0))) + IF(I17="Low",VLOOKUP(N17,lst_tshirt_tc,2,FALSE),IF(I17="Medium",VLOOKUP(N17,lst_tshirt_tc,3,FALSE),IF(I17="High",VLOOKUP(N17,lst_tshirt_tc,4,FALSE),0))) -> 0 | N17: =IF(ISBLANK(G17),F17,VLOOKUP(G17,lst_SP_to_TShirt,2,FALSE)) -> zero
A18: 16 | B18: Capability 2 | C18: Feature 16 | E18: Later | F18: zero | H18: Medium | I18: Medium | J18: =IFERROR((K18-K18*M18),0) -> 0 | K18: =IFERROR((IF(ISBLANK(G18),VLOOKUP(F18,lst_TShirt_2_SP_Avg,2,FALSE),G18)),0) -> 0 | L18: =K18+K18*M18 -> 0 | M18: =IF(H18="Low",VLOOKUP(N18,lst_tshirt_bu,2,FALSE),IF(H18="Medium",VLOOKUP(N18,lst_tshirt_bu,3,FALSE),IF(H18="High",VLOOKUP(N18,lst_tshirt_bu,4,FALSE),0))) + IF(I18="Low",VLOOKUP(N18,lst_tshirt_tc,2,FALSE),IF(I18="Medium",VLOOKUP(N18,lst_tshirt_tc,3,FALSE),IF(I18="High",VLOOKUP(N18,lst_tshirt_tc,4,FALSE),0))) -> 0 | N18: =IF(ISBLANK(G18),F18,VLOOKUP(G18,lst_SP_to_TShirt,2,FALSE)) -> zero
... A25: 23 | B25: Capability 2 | C25: Feature 23 | E25: Last | F25: zero | H25: Low | I25: Low | J25: =IFERROR((K25-K25*M25),0) -> 0 | K25: =IFERROR((IF(ISBLANK(G25),VLOOKUP(F25,lst_TShirt_2_SP_Avg,2,FALSE),G25)),0) -> 0 | L25: =K25+K25*M25 -> 0 | M25: =IF(H25="Low",VLOOKUP(N25,lst_tshirt_bu,2,FALSE),IF(H25="Medium",VLOOKUP(N25,lst_tshirt_bu,3,FALSE),IF(H25="High",VLOOKUP(N25,lst_tshirt_bu,4,FALSE),0))) + IF(I25="Low",VLOOKUP(N25,lst_tshirt_tc,2,FALSE),IF(I25="Medium",VLOOKUP(N25,lst_tshirt_tc,3,FALSE),IF(I25="High",VLOOKUP(N25,lst_tshirt_tc,4,FALSE),0))) -> 0 | N25: =IF(ISBLANK(G25),F25,VLOOKUP(G25,lst_SP_to_TShirt,2,FALSE)) -> zero
A26: Total | J26: =SUBTOTAL(109,Table1[BEST CASE]) -> 22 | K26: =SUBTOTAL(109,Table1[MOST LIKELY]) -> 24 | L26: =SUBTOTAL(109,Table1[WORST CASE]) -> 26

Sheet Features Analysis
B2: Phase: | C2: Next
B4: Features analysis by Size | I4: Features analysis by Uncertainty | O4: Features analysis by Complexity
B5: Row Labels | C5: %tage | D5: Number of Uss | E5: Best Case (SP) | F5: Most Likely (SP) | G5: Worst Case (SP) | I5: Row Labels | J5: %tage | K5: Best Case (SP) | L5: Most Likely (SP) | M5: Worst Case (SP) | O5: Row Labels | P5: %tage | Q5: Best Case (SP) | R5: Most Likely (SP) | S5: Worst Case (SP)
B6: XS | C6: =SUM(E6:G6)/SUM($E$12:$G$12) -> 0 | D6: {=SUMPRODUCT((Table1[Tshirt Sizing]=B6)*IF($C$2="(All)",1,(Table1[Phase]=$C$2)))} -> 0 | E6: {=SUMPRODUCT((Table1[Tshirt Sizing]=B6)*IF($C$2="(All)",1,(Table1[Phase]=$C$2))*Table1[BEST CASE])} -> 0 | F6: {=SUMPRODUCT((Table1[Tshirt Sizing]=B6)*IF($C$2="(All)",1,(Table1[Phase]=$C$2))*Table1[MOST LIKELY])} -> 0 | G6: {=SUMPRODUCT((Table1[Tshirt Sizing]=B6)*IF($C$2="(All)",1,(Table1[Phase]=$C$2))*Table1[WORST CASE])} -> 0 | I6: Low | J6: =SUM(K6:M6)/SUM($K$9:$M$9) -> 1 | K6: {=SUMPRODUCT((Table1[Business Uncertainty]=I6)*IF($C$2="(All)",1,(Table1[Phase]=$C$2))*Table1[BEST CASE])} -> 22 | L6: {=SUMPRODUCT((Table1[Business Uncertainty]=I6)*IF($C$2="(All)",1,(Table1[Phase]=$C$2))*Table1[MOST LIKELY])} -> 24 | M6: {=SUMPRODUCT((Table1[Business Uncertainty]=I6)*IF($C$2="(All)",1,(Table1[Phase]=$C$2))*Table1[WORST CASE])} -> 26 | O6: Low | P6: =SUM(Q6:S6)/SUM($Q$9:$S$9) -> 0.33333333 | Q6: {=SUMPRODUCT((Table1[Technical Complexity]=O6)*IF($C$2="(All)",1,(Table1[Phase]=$C$2))*Table1[BEST CASE])} -> 8 | R6: {=SUMPRODUCT((Table1[Technical Complexity]=O6)*IF($C$2="(All)",1,(Table1[Phase]=$C$2))*Table1[MOST LIKELY])} -> 8 | S6: {=SUMPRODUCT((Table1[Technical Complexity]=O6)*IF($C$2="(All)",1,(Table1[Phase]=$C$2))*Table1[WORST CASE])} -> 8
B7: S | C7: =SUM(E7:G7)/SUM($E$12:$G$12) -> 0.33333333 | D7: {=SUMPRODUCT((Table1[Tshirt Sizing]=B7)*IF($C$2="(All)",1,(Table1[Phase]=$C$2)))} -> 2 | E7: {=SUMPRODUCT((Table1[Tshirt Sizing]=B7)*IF($C$2="(All)",1,(Table1[Phase]=$C$2))*Table1[BEST CASE])} -> 7.6 | F7: {=SUMPRODUCT((Table1[Tshirt Sizing]=B7)*IF($C$2="(All)",1,(Table1[Phase]=$C$2))*Table1[MOST LIKELY])} -> 8 | G7: {=SUMPRODUCT((Table1[Tshirt Sizing]=B7)*IF($C$2="(All)",1,(Table1[Phase]=$C$2))*Table1[WORST CASE])} -> 8.4 | I7: Medium | J7: =SUM(K7:M7)/SUM($K$9:$M$9) -> 0 | K7: {=SUMPRODUCT((Table1[Business Uncertainty]=I7)*IF($C$2="(All)",1,(Table1[Phase]=$C$2))*Table1[BEST CASE])} -> 0 | L7: {=SUMPRODUCT((Table1[Business Uncertainty]=I7)*IF($C$2="(All)",1,(Table1[Phase]=$C$2))*Table1[MOST LIKELY])} -> 0 | M7: {=SUMPRODUCT((Table1[Business Uncertainty]=I7)*IF($C$2="(All)",1,(Table1[Phase]=$C$2))*Table1[WORST CASE])} -> 0 | O7: Medium | P7: =SUM(Q7:S7)/SUM($Q$9:$S$9) -> 0.33333333 | Q7: {=SUMPRODUCT((Table1[Technical Complexity]=O7)*IF($C$2="(All)",1,(Table1[Phase]=$C$2))*Table1[BEST CASE])} -> 7.6 | R7: {=SUMPRODUCT((Table1[Technical Complexity]=O7)*IF($C$2="(All)",1,(Table1[Phase]=$C$2))*Table1[MOST LIKELY])} -> 8 | S7: {=SUMPRODUCT((Table1[Technical Complexity]=O7)*IF($C$2="(All)",1,(Table1[Phase]=$C$2))*Table1[WORST CASE])} -> 8.4
B8: M | C8: =SUM(E8:G8)/SUM($E$12:$G$12) -> 0.66666667 | D8: {=SUMPRODUCT((Table1[Tshirt Sizing]=B8)*IF($C$2="(All)",1,(Table1[Phase]=$C$2)))} -> 2 | E8: {=SUMPRODUCT((Table1[Tshirt Sizing]=B8)*IF($C$2="(All)",1,(Table1[Phase]=$C$2))*Table1[BEST CASE])} -> 14.4 | F8: {=SUMPRODUCT((Table1[Tshirt Sizing]=B8)*IF($C$2="(All)",1,(Table1[Phase]=$C$2))*Table1[MOST LIKELY])} -> 16 | G8: {=SUMPRODUCT((Table1[Tshirt Sizing]=B8)*IF($C$2="(All)",1,(Table1[Phase]=$C$2))*Table1[WORST CASE])} -> 17.6 | I8: High | J8: =SUM(K8:M8)/SUM($K$9:$M$9) -> 0 | K8: {=SUMPRODUCT((Table1[Business Uncertainty]=I8)*IF($C$2="(All)",1,(Table1[Phase]=$C$2))*Table1[BEST CASE])} -> 0 | L8: {=SUMPRODUCT((Table1[Business Uncertainty]=I8)*IF($C$2="(All)",1,(Table1[Phase]=$C$2))*Table1[MOST LIKELY])} -> 0 | M8: {=SUMPRODUCT((Table1[Business Uncertainty]=I8)*IF($C$2="(All)",1,(Table1[Phase]=$C$2))*Table1[WORST CASE])} -> 0 | O8: High | P8: =SUM(Q8:S8)/SUM($Q$9:$S$9) -> 0.33333333 | Q8: {=SUMPRODUCT((Table1[Technical Complexity]=O8)*IF($C$2="(All)",1,(Table1[Phase]=$C$2))*Table1[BEST CASE])} -> 6.4 | R8: {=SUMPRODUCT((Table1[Technical Complexity]=O8)*IF($C$2="(All)",1,(Table1[Phase]=$C$2))*Table1[MOST LIKELY])} -> 8 | S8: {=SUMPRODUCT((Table1[Technical Complexity]=O8)*IF($C$2="(All)",1,(Table1[Phase]=$C$2))*Table1[WORST CASE])} -> 9.6
B9: L | C9: =SUM(E9:G9)/SUM($E$12:$G$12) -> 0 | D9: {=SUMPRODUCT((Table1[Tshirt Sizing]=B9)*IF($C$2="(All)",1,(Table1[Phase]=$C$2)))} -> 0 | E9: {=SUMPRODUCT((Table1[Tshirt Sizing]=B9)*IF($C$2="(All)",1,(Table1[Phase]=$C$2))*Table1[BEST CASE])} -> 0 | F9: {=SUMPRODUCT((Table1[Tshirt Sizing]=B9)*IF($C$2="(All)",1,(Table1[Phase]=$C$2))*Table1[MOST LIKELY])} -> 0 | G9: {=SUMPRODUCT((Table1[Tshirt Sizing]=B9)*IF($C$2="(All)",1,(Table1[Phase]=$C$2))*Table1[WORST CASE])} -> 0 | I9: Total | J9: =SUM(J6:J8) -> 1 | K9: =SUM(K6:K8) -> 22 | L9: =SUM(L6:L8) -> 24 | M9: =SUM(M6:M8) -> 26 | O9: Total | P9: =SUM(P6:P8) -> 1 | Q9: =SUM(Q6:Q8) -> 22 | R9: =SUM(R6:R8) -> 24 | S9: =SUM(S6:S8) -> 26
B10: XL | C10: =SUM(E10:G10)/SUM($E$12:$G$12) -> 0 | D10: {=SUMPRODUCT((Table1[Tshirt Sizing]=B10)*IF($C$2="(All)",1,(Table1[Phase]=$C$2)))} -> 0 | E10: {=SUMPRODUCT((Table1[Tshirt Sizing]=B10)*IF($C$2="(All)",1,(Table1[Phase]=$C$2))*Table1[BEST CASE])} -> 0 | F10: {=SUMPRODUCT((Table1[Tshirt Sizing]=B10)*IF($C$2="(All)",1,(Table1[Phase]=$C$2))*Table1[MOST LIKELY])} -> 0 | G10: {=SUMPRODUCT((Table1[Tshirt Sizing]=B10)*IF($C$2="(All)",1,(Table1[Phase]=$C$2))*Table1[WORST CASE])} -> 0
B11: XXL | C11: =SUM(E11:G11)/SUM($E$12:$G$12) -> 0 | D11: {=SUMPRODUCT((Table1[Tshirt Sizing]=B11)*IF($C$2="(All)",1,(Table1[Phase]=$C$2)))} -> 0 | E11: {=SUMPRODUCT((Table1[Tshirt Sizing]=B11)*IF($C$2="(All)",1,(Table1[Phase]=$C$2))*Table1[BEST CASE])} -> 0 | F11: {=SUMPRODUCT((Table1[Tshirt Sizing]=B11)*IF($C$2="(All)",1,(Table1[Phase]=$C$2))*Table1[MOST LIKELY])} -> 0 | G11: {=SUMPRODUCT((Table1[Tshirt Sizing]=B11)*IF($C$2="(All)",1,(Table1[Phase]=$C$2))*Table1[WORST CASE])} -> 0
B12: Total | C12: =SUM(C6:C11) -> 1 | D12: =SUM(D6:D11) -> 4 | E12: =SUM(E6:E11) -> 22 | F12: =SUM(F6:F11) -> 24 | G12: =SUM(G6:G11) -> 26

Sheet Cone of Uncertainty
C2: Project timeline | D2: No of Sprints in Build Phase | E2: Total no of Sprint including (setup, UAT ..) | F2: Y
C3: Best Case | D3: 0 | E3: 0 | F3: 0
D4: =ROUNDUP(Table1[[#Totals],[BEST CASE]]/avgVelocity,0) + D14 +D15 -> 4 | E4: =D4+D14+D15 -> 6 | F4: ='Cone of Uncertainty'!D20 -> 10
C5: Most Likely | D5: 0 | E5: 0 | F5: 0
D6: =ROUNDUP(Table1[[#Totals],[MOST LIKELY]]/avgVelocity,0) + D14 +D15 -> 4 | E6: =D6+D14+D15 -> 6 | F6: ='Cone of Uncertainty'!D20 -> 10
C7: Worst Case | D7: 0 | E7: 0 | F7: 0
D8: =ROUNDUP(Table1[[#Totals],[WORST CASE]]/avgVelocity,0) + D14 +D15 -> 4 | E8: =D8+D14+D15 -> 6 | F8: ='Cone of Uncertainty'!D20 -> 10
C9: Threshold | D9: 0 | E9: 0 | F9: ='Cone of Uncertainty'!D20 -> 10
D10: =ROUNDUP(Table1[[#Totals],[MOST LIKELY]]/avgVelocity + 'Cone of Uncertainty'!D21,0) -> 22 | E10: =ROUNDUP((Table1[[#Totals],[MOST LIKELY]] + D14 + D15)/avgVelocity + 'Cone of Uncertainty'!D21,0) -> 22 | F10: ='Cone of Uncertainty'!D20 -> 10
B13: Build | C13: Average Velocity(SP) per Sprint | D13: 20
B14: Operate | C14: Number of sprints for Operate (handover, releases, UAT, SIT, application support, etc.) | D14: 0
B15: Technical Items | C15: 1. Environment setup for teams (install tools, access to cloud services etc.) 2. Create all environments needed by the engagement: dev, system test, pre-prod, production. 3. Create a delivery pipeline. 4. NFRs 5. Security testing | D15: 2
C18: Visual Parameters
C19: Cone Size | D19: ='Cone of Uncertainty'!E8-'Cone of Uncertainty'!E4 -> 0
C20: Threshold | D20: 10
C21: Length of threshold | D21: 20

Sheet byUncertainty
A1: Phase | B1: (All)
A3: Business Uncertainty / Size | B3: %tage | C3: Best Case (SP) | D3: Most Likely (SP) | E3: Worst Case (SP)
A4: Low | B4: 0.19575699 | C4: 75.65 | D4: 101.5 | E4: 127.35
A5: Medium | B5: 0.27193828 | C5: 83.8 | D5: 141 | E5: 198.2
A6: High | B6: 0.53230473 | C6: 69.7 | D6: 276 | E6: 482.3
A7: Total | B7: 1 | C7: 229.15 | D7: 518.5 | E7: 807.85

Sheet byComplexity
A1: Phase | B1: (All)
A3: Technical Complexity / Size | B3: %tage | C3: Best Case (SP) | D3: Most Likely (SP) | E3: Worst Case (SP)
A4: Low | B4: 0.42912247 | C4: 117.3 | D4: 222.5 | E4: 327.7
A5: Medium | B5: 0.49373192 | C5: 103.85 | D5: 256 | E5: 408.15
A6: High | B6: 0.077145612 | C6: 8 | D6: 40 | E6: 72
A7: Total | B7: 1 | C7: 229.15 | D7: 518.5 | E7: 807.85

Sheet Assumtions
B2: # | C2: Assumptions
B3: 1
B4: 2
B5: 3
B6: 4
B7: 5
B8: 6
B9: 7
B10: 8
B11: 9
B12: 10
B13: 11
B14: 12

Sheet Definition of Done
A1: This template uses an average velocity (Story Points) to calculate the cone of uncertainty (duration interval). For that to be valid you'll need the estimation team to allign on what "done" means and what activities are included. The below is an example as a starting points and should be tailored case-by-case
A4: Development
B5: Technical Implementation Plan confirmed with architects/TL [if needed].
B6: Code written and tested locally.
B7: Unit Tests developed for Back-end ( 80% code coverage) and Front-end ( 60% code coverage).
B8: Code reviewed and approved by at least one mandatory approval.
B9: Documentation of model/controllers/sequence diagrams [if needed].
B10: IDs for FE elements ( where needed). - checked on code review & testing.
B11: Configuration check - (if needed ) added in release notes.
B12: Release notes updated.
B13: Sonar execution on review - no critical issues accepted.
B14: English labels available in CMS ( if needed).
B15: All defects reported by testing fixed.
A16: Deployment/Demo
B17: Changes deployed successfully to Openshift Director env (no build error + sonar passed successfully ) >= 5 SP (2 days before sprint ends), only bug fixing will be allowed.
B18: Deployment freeze also 3 hours before demo.
A19: Testing
B20: Test cases written in Zephyr.
B21: Application tested against the mock layer, including error cases and edge.
B22: Manual functional test 100% test coverage on test environment.
B23: Manual test (basic and advanced) cases executed and passing.
B24: Exploratory testing executed.
B25: Testing passed 100% on Test Environment.
B26: All issues reported as bugs and linked to the stories.
B27: Acceptance criteria fulfilled.
B28: Test data is documented.
B29: NFR fulfilled.
B30: Quality Acceptance.
B31: No issues with severity worse than Major.
... B33: User story is updated with latest information/requirements.
A34: Automated testing
B35: Automated tests written.
B36: Automated tests committed to Git.
B37: Automated tests executed and validated.
A38: Other considerations
B39: (TBD story by story
B40: OR add a separate story)
B41: *all to be covered with Acceptance criteria.
B42: Performance.
B43: Security.
...

Sheet Team Shape
B2: Delivery Team(s) Shape
B3: Name of Person (if known) | C3: Role | D3: Grade
C4: Scrum Master | D4: CL
C5: Senior Developer | D5: SC
C6: Developer | D6: SE
C7: Developer | D7: SE
C8: Senior Tester | D8: CL
C9: Tester | D9: EN
C10: Architect | D10: SC
C11: Project Manager | D11: CL
C12: Business Analyst | D12: CL

Sheet ConeOfUncertainty Setup
C3: Value | D3: Business Uncertainty Low | E3: Business Uncertainty Medium | F3: Business Uncertainty High | J3: Sizing GoldieLocks: Tshirt to SP Average Lookup | O3: Business Uncertainty Values | S3: Phases
C4: zero | D4: 0 | E4: 0 | F4: 0 | J4: zero | K4: 0 | O4: Low | S4: Next
C5: XS | D5: 0 | E5: 0.05 | F5: 0.1 | J5: XS | K5: 1.5 | O5: Medium | S5: Later
C6: S | D6: 0 | E6: 0.1 | F6: 0.2 | J6: S | K6: 4 | O6: High | S6: Last
C7: M | D7: 0 | E7: 0.2 | F7: 0.25 | J7: M | K7: 10.5 | S7: (All)
C8: L | D8: 0.2 | E8: 0.25 | F8: 0.3 | J8: L | K8: 20
C9: XL | D9: 0.25 | E9: 0.3 | F9: 0.4 | J9: XL | K9: 40
C10: XXL | D10: 0.3 | E10: 0.4 | F10: 0.5 | J10: XXL | K10: 100
C12: Value | D12: Technical Complexity Low | E12: Technical Complexity Medium | F12: Technical Complexity High | J12: Sizing GoldieLocks: Tshirt to SP Average Lookup | O12: Technical Complexity Values
C13: zero | D13: 0 | E13: 0 | F13: 0 | J13: 0 | K13: zero | O13: Low
C14: XS | D14: 0 | E14: 0 | F14: 0.05 | J14: 1 | K14: XS | O14: Medium
C15: S | D15: 0 | E15: 0.05 | F15: 0.1 | J15: 2 | K15: XS | O15: High
C16: M | D16: 0 | E16: 0.1 | F16: 0.2 | J16: 3 | K16: S
C17: L | D17: 0.1 | E17: 0.15 | F17: 0.3 | J17: 5 | K17: S
C18: XL | D18: 0.15 | E18: 0.2 | F18: 0.4 | J18: 8 | K18: M
C19: XXL | D19: 0.2 | E19: 0.4 | F19: 0.5 | J19: 13 | K19: M
J20: 20 | K20: L
J21: 40 | K21: XL
J22: 100 | K22: XXL
